Workbook

Sheet ConsumerPreferencesTable
A1: Consumer_ID | B1: Preferred_Cuisine
A2: U1001 | B2: American
A3: U1002 | B3: Mexican
A4: U1003 | B4: Mexican
A5: U1004 | B5: Bakery
A6: U1004 | B6: Breakfast
A7: U1004 | B7: Japanese
A8: U1004 | B8: Contemporary
A9: U1004 | B9: Mexican
A10: U1004 | B10: Bagels
A11: U1004 | B11: Coffee Shop
A12: U1004 | B12: Continental
... A329: U1138 | B329: Pizzeria

Sheet consumer_preferences
A1: Consumer_ID | B1: Preferred_Cuisine
A2: U1001 | B2: American
A3: U1002 | B3: Mexican
A4: U1003 | B4: Mexican
A5: U1004 | B5: Bakery
A6: U1004 | B6: Breakfast
A7: U1004 | B7: Japanese
A8: U1004 | B8: Contemporary
A9: U1004 | B9: Mexican
A10: U1004 | B10: Bagels
A11: U1004 | B11: Coffee Shop
A12: U1004 | B12: Continental
... A329: U1138 | B329: Pizzeria

Sheet ConsumersTable
A1: Consumer_ID | B1: Consumer_City | C1: Consumer_State | D1: Consumer_Country | E1: Consumer_Latitude | F1: Consumer_Longitude | G1: Consumer_Smoker | H1: Consumer_Drink_Level | I1: Consumer_Transportation_Method | J1: Consumer_Marital_Status | K1: Consumer_Children | L1: Consumer_Age | M1: Consumer_Occupation | N1: Consumer_Budget | O1: Preferred_Cuisine | P1: Age_Bracket
A2: U1001 | B2: San Luis Potosi | C2: San Luis Potosi | D2: Mexico | E2: 22.139997 | F2: -100.9788 | G2: No | H2: Abstemious | I2: On Foot | J2: Single | K2: Independent | L2: 23 | M2: Student | N2: Medium | O2: American | P2: =IF(L2<=12,"Children", IF(L2<=19,"Teenagers", IF(L2<=49,"Young Adult", IF(L2>=50,"Old","Unknown")))) -> Young Adult
A3: U1002 | B3: San Luis Potosi | C3: San Luis Potosi | D3: Mexico | E3: 22.150087 | F3: -100.98332 | G3: No | H3: Abstemious | I3: Public | J3: Single | K3: Independent | L3: 22 | M3: Student | N3: Low | O3: Mexican | P3: =IF(L3<=12,"Children", IF(L3<=19,"Teenagers", IF(L3<=49,"Young Adult", IF(L3>=50,"Old","Unknown")))) -> Young Adult
A4: U1003 | B4: San Luis Potosi | C4: San Luis Potosi | D4: Mexico | E4: 22.119847 | F4: -100.94653 | G4: No | H4: Social Drinker | I4: Public | J4: Single | K4: Independent | L4: 23 | M4: Student | N4: Low | O4: Mexican | P4: =IF(L4<=12,"Children", IF(L4<=19,"Teenagers", IF(L4<=49,"Young Adult", IF(L4>=50,"Old","Unknown")))) -> Young Adult
A5: U1004 | B5: Cuernavaca | C5: Morelos | D5: Mexico | E5: 18.867 | F5: -99.183 | G5: No | H5: Abstemious | I5: Public | J5: Single | K5: Independent | L5: 72 | M5: Employed | N5: Medium | O5: Bakery | P5: =IF(L5<=12,"Children", IF(L5<=19,"Teenagers", IF(L5<=49,"Young Adult", IF(L5>=50,"Old","Unknown")))) -> Old
A6: U1005 | B6: San Luis Potosi | C6: San Luis Potosi | D6: Mexico | E6: 22.183477 | F6: -100.95989 | G6: No | H6: Abstemious | I6: Public | J6: Single | K6: Independent | L6: 20 | M6: Student | N6: Medium | O6: American | P6: =IF(L6<=12,"Children", IF(L6<=19,"Teenagers", IF(L6<=49,"Young Adult", IF(L6>=50,"Old","Unknown")))) -> Young Adult
A7: U1006 | B7: San Luis Potosi | C7: San Luis Potosi | D7: Mexico | E7: 22.15 | F7: -100.983 | G7: Yes | H7: Social Drinker | I7: Car | J7: Single | K7: Independent | L7: 23 | M7: Student | N7: Medium | O7: Mexican | P7: =IF(L7<=12,"Children", IF(L7<=19,"Teenagers", IF(L7<=49,"Young Adult", IF(L7>=50,"Old","Unknown")))) -> Young Adult
A8: U1007 | B8: San Luis Potosi | C8: San Luis Potosi | D8: Mexico | E8: 22.118464 | F8: -100.93826 | G8: No | H8: Casual Drinker | I8: Public | J8: Single | K8: Independent | L8: 23 | M8: Student | N8: Low | O8: Family | P8: =IF(L8<=12,"Children", IF(L8<=19,"Teenagers", IF(L8<=49,"Young Adult", IF(L8>=50,"Old","Unknown")))) -> Young Adult
A9: U1008 | B9: San Luis Potosi | C9: San Luis Potosi | D9: Mexico | E9: 22.122989 | F9: -100.92381 | G9: No | H9: Social Drinker | I9: Public | J9: Single | K9: Independent | L9: 23 | M9: Student | N9: Low | O9: Coffee Shop | P9: =IF(L9<=12,"Children", IF(L9<=19,"Teenagers", IF(L9<=49,"Young Adult", IF(L9>=50,"Old","Unknown")))) -> Young Adult
A10: U1009 | B10: San Luis Potosi | C10: San Luis Potosi | D10: Mexico | E10: 22.159427 | F10: -100.99045 | G10: No | H10: Abstemious | I10: On Foot | J10: Single | K10: Kids | L10: 21 | M10: Student | N10: Medium | O10: Diner | P10: =IF(L10<=12,"Children", IF(L10<=19,"Teenagers", IF(L10<=49,"Young Adult", IF(L10>=50,"Old","Unknown")))) -> Young Adult
A11: U1010 | B11: San Luis Potosi | C11: San Luis Potosi | D11: Mexico | E11: 22.190889 | F11: -100.99867 | G11: No | H11: Social Drinker | I11: Car | J11: Married | K11: Kids | L11: 25 | M11: Student | N11: Medium | O11: Mexican | P11: =IF(L11<=12,"Children", IF(L11<=19,"Teenagers", IF(L11<=49,"Young Adult", IF(L11>=50,"Old","Unknown")))) -> Young Adult
A12: U1011 | B12: Ciudad Victoria | C12: Tamaulipas | D12: Mexico | E12: 23.724972 | F12: -99.152856 | G12: No | H12: Abstemious | I12: Public | J12: Single | K12: Independent | L12: 23 | M12: Student | N12: Medium | O12: Mexican | P12: =IF(L12<=12,"Children", IF(L12<=19,"Teenagers", IF(L12<=49,"Young Adult", IF(L12>=50,"Old","Unknown")))) -> Young Adult
A13: U1012 | B13: Cuernavaca | C13: Morelos | D13: Mexico | E13: 18.813348 | F13: -99.243697 | G13: No | H13: Casual Drinker | I13: Public | J13: Single | K13: Independent | L13: 24 | M13: Student | N13: Medium | O13: Latin American | P13: =IF(L13<=12,"Children", IF(L13<=19,"Teenagers", IF(L13<=49,"Young Adult", IF(L13>=50,"Old","Unknown")))) -> Young Adult
... A17: U1016 | B17: San Luis Potosi | C17: San Luis Potosi | D17: Mexico | E17: 22.156247 | F17: -100.9774 | G17: No | H17: Casual Drinker | I17: On Foot | J17: Single | K17: Independent | L17: 21 | M17: Student | N17: Medium | O17: Coffee Shop | P17: =IF(L17<=12,"Children", IF(L17<=19,"Teenagers", IF(L17<=49,"Young Adult", IF(L17>=50,"Old","Unknown")))) -> Young Adult
A18: U1017 | B18: Cuernavaca | C18: Morelos | D18: Mexico | E18: 18.952615 | F18: -99.201616 | G18: No | H18: Casual Drinker | I18: Public | J18: Single | L18: 21 | M18: Employed | N18: Medium | O18: Chinese | P18: =IF(L18<=12,"Children", IF(L18<=19,"Teenagers", IF(L18<=49,"Young Adult", IF(L18>=50,"Old","Unknown")))) -> Young Adult
A19: U1018 | B19: San Luis Potosi | C19: San Luis Potosi | D19: Mexico | E19: 22.190949 | F19: -100.9179 | G19: Yes | H19: Casual Drinker | I19: Public | J19: Single | K19: Independent | L19: 23 | M19: Student | N19: Low | O19: Mexican | P19: =IF(L19<=12,"Children", IF(L19<=19,"Teenagers", IF(L19<=49,"Young Adult", IF(L19>=50,"Old","Unknown")))) -> Young Adult
A20: U1019 | B20: San Luis Potosi | C20: San Luis Potosi | D20: Mexico | E20: 22.153385 | F20: -100.97529 | G20: No | H20: Casual Drinker | I20: Public | J20: Single | K20: Independent | L20: 23 | M20: Student | N20: Medium | O20: Family | P20: =IF(L20<=12,"Children", IF(L20<=19,"Teenagers", IF(L20<=49,"Young Adult", IF(L20>=50,"Old","Unknown")))) -> Young Adult
A21: U1020 | B21: Cuernavaca | C21: Morelos | D21: Mexico | E21: 18.878189 | F21: -99.222969 | G21: No | H21: Abstemious | I21: Public | J21: Single | K21: Independent | L21: 30 | M21: Employed | N21: Medium | O21: Mexican | P21: =IF(L21<=12,"Children", IF(L21<=19,"Teenagers", IF(L21<=49,"Young Adult", IF(L21>=50,"Old","Unknown")))) -> Young Adult
A22: U1021 | B22: Ciudad Victoria | C22: Tamaulipas | D22: Mexico | E22: 23.730569 | F22: -99.171883 | G22: No | H22: Social Drinker | I22: Car | J22: Single | K22: Dependent | L22: 28 | M22: Student | N22: Medium | O22: Pizzeria | P22: =IF(L22<=12,"Children", IF(L22<=19,"Teenagers", IF(L22<=49,"Young Adult", IF(L22>=50,"Old","Unknown")))) -> Young Adult
A23: U1022 | B23: San Luis Potosi | C23: San Luis Potosi | D23: Mexico | E23: 22.146708 | F23: -100.96435 | G23: No | H23: Casual Drinker | I23: Car | J23: Single | K23: Independent | L23: 22 | M23: Student | N23: Medium | O23: Mexican | P23: =IF(L23<=12,"Children", IF(L23<=19,"Teenagers", IF(L23<=49,"Young Adult", IF(L23>=50,"Old","Unknown")))) -> Young Adult
A24: U1023 | B24: Ciudad Victoria | C24: Tamaulipas | D24: Mexico | E24: 23.752943 | F24: -99.166589 | G24: No | H24: Casual Drinker | I24: Car | J24: Single | K24: Independent | L24: 24 | M24: Student | N24: Low | O24: Mexican | P24: =IF(L24<=12,"Children", IF(L24<=19,"Teenagers", IF(L24<=49,"Young Adult", IF(L24>=50,"Old","Unknown")))) -> Young Adult
A25: U1024 | B25: San Luis Potosi | C25: San Luis Potosi | D25: Mexico | E25: 22.154021 | F25: -100.97603 | H25: Abstemious | L25: 82 | O25: Afghan | P25: =IF(L25<=12,"Children", IF(L25<=19,"Teenagers", IF(L25<=49,"Young Adult", IF(L25>=50,"Old","Unknown")))) -> Old
A26: U1025 | B26: San Luis Potosi | C26: San Luis Potosi | D26: Mexico | E26: 22.125603 | F26: -100.90784 | G26: No | H26: Social Drinker | I26: Public | J26: Single | L26: 22 | M26: Student | N26: Medium | O26: Mexican | P26: =IF(L26<=12,"Children", IF(L26<=19,"Teenagers", IF(L26<=49,"Young Adult", IF(L26>=50,"Old","Unknown")))) -> Young Adult
A27: U1026 | B27: Ciudad Victoria | C27: Tamaulipas | D27: Mexico | E27: 23.733 | F27: -99.133 | G27: No | H27: Abstemious | I27: Public | J27: Single | K27: Independent | L27: 23 | M27: Student | N27: Medium | O27: Mexican | P27: =IF(L27<=12,"Children", IF(L27<=19,"Teenagers", IF(L27<=49,"Young Adult", IF(L27>=50,"Old","Unknown")))) -> Young Adult
A28: U1027 | B28: San Luis Potosi | C28: San Luis Potosi | D28: Mexico | E28: 22.16515 | F28: -100.98701 | G28: Yes | H28: Social Drinker | I28: Public | J28: Single | K28: Independent | L28: 23 | M28: Student | N28: Low | O28: Family | P28: =IF(L28<=12,"Children", IF(L28<=19,"Teenagers", IF(L28<=49,"Young Adult", IF(L28>=50,"Old","Unknown")))) -> Young Adult
A29: U1028 | B29: Ciudad Victoria | C29: Tamaulipas | D29: Mexico | E29: 23.752874 | F29: -99.169242 | G29: No | H29: Abstemious | I29: Public | J29: Single | K29: Independent | L29: 23 | M29: Student | N29: Medium | O29: Mexican | P29: =IF(L29<=12,"Children", IF(L29<=19,"Teenagers", IF(L29<=49,"Young Adult", IF(L29>=50,"Old","Unknown")))) -> Young Adult
A30: U1029 | B30: San Luis Potosi | C30: San Luis Potosi | D30: Mexico | E30: 22.151796 | F30: -100.98907 | G30: Yes | H30: Casual Drinker | I30: Public | J30: Single | K30: Independent | L30: 22 | M30: Student | N30: Low | O30: Mexican | P30: =IF(L30<=12,"Children", IF(L30<=19,"Teenagers", IF(L30<=49,"Young Adult", IF(L30>=50,"Old","Unknown")))) -> Young Adult
A31: U1030 | B31: Cuernavaca | C31: Morelos | D31: Mexico | E31: 18.844818 | F31: -99.182758 | G31: No | H31: Casual Drinker | I31: On Foot | J31: Single | K31: Independent | L31: 21 | M31: Student | N31: Medium | O31: Mexican | P31: =IF(L31<=12,"Children", IF(L31<=19,"Teenagers", IF(L31<=49,"Young Adult", IF(L31>=50,"Old","Unknown")))) -> Young Adult
A32: U1031 | B32: Ciudad Victoria | C32: Tamaulipas | D32: Mexico | E32: 23.735698 | F32: -99.159851 | G32: No | H32: Abstemious | J32: Married | K32: Kids | L32: 20 | M32: Unemployed | N32: Medium | O32: Mexican | P32: =IF(L32<=12,"Children", IF(L32<=19,"Teenagers", IF(L32<=49,"Young Adult", IF(L32>=50,"Old","Unknown")))) -> Young Adult
A33: U1032 | B33: San Luis Potosi | C33: San Luis Potosi | D33: Mexico | E33: 22.169184 | F33: -100.98684 | G33: No | H33: Abstemious | I33: Public | J33: Single | K33: Independent | L33: 23 | M33: Student | N33: Medium | O33: Mexican | P33: =IF(L33<=12,"Children", IF(L33<=19,"Teenagers", IF(L33<=49,"Young Adult", IF(L33>=50,"Old","Unknown")))) -> Young Adult
A34: U1033 | B34: San Luis Potosi | C34: San Luis Potosi | D34: Mexico | E34: 22.15 | F34: -100.983 | G34: No | H34: Social Drinker | I34: On Foot | J34: Single | L34: 21 | M34: Student | N34: Low | O34: Mexican | P34: =IF(L34<=12,"Children", IF(L34<=19,"Teenagers", IF(L34<=49,"Young Adult", IF(L34>=50,"Old","Unknown")))) -> Young Adult
A35: U1034 | B35: San Luis Potosi | C35: San Luis Potosi | D35: Mexico | E35: 22.137178 | F35: -101.01317 | G35: No | H35: Casual Drinker | I35: Public | J35: Single | K35: Independent | L35: 22 | M35: Student | N35: Medium | O35: Mexican | P35: =IF(L35<=12,"Children", IF(L35<=19,"Teenagers", IF(L35<=49,"Young Adult", IF(L35>=50,"Old","Unknown")))) -> Young Adult
A36: U1035 | B36: Cuernavaca | C36: Morelos | D36: Mexico | E36: 18.839671 | F36: -99.223897 | G36: Yes | H36: Casual Drinker | I36: Car | J36: Single | K36: Independent | L36: 27 | M36: Student | N36: Medium | O36: Family | P36: =IF(L36<=12,"Children", IF(L36<=19,"Teenagers", IF(L36<=49,"Young Adult", IF(L36>=50,"Old","Unknown")))) -> Young Adult
A37: U1036 | B37: San Luis Potosi | C37: San Luis Potosi | D37: Mexico | E37: 22.160572 | F37: -100.98942 | G37: No | H37: Social Drinker | I37: Public | J37: Single | K37: Independent | L37: 21 | M37: Student | N37: Medium | O37: Mexican | P37: =IF(L37<=12,"Children", IF(L37<=19,"Teenagers", IF(L37<=49,"Young Adult", IF(L37>=50,"Old","Unknown")))) -> Young Adult
A38: U1037 | B38: San Luis Potosi | C38: San Luis Potosi | D38: Mexico | E38: 22.15031 | F38: -100.90054 | G38: No | H38: Social Drinker | I38: Public | J38: Single | K38: Independent | L38: 22 | M38: Student | N38: Low | O38: Mexican | P38: =IF(L38<=12,"Children", IF(L38<=19,"Teenagers", IF(L38<=49,"Young Adult", IF(L38>=50,"Old","Unknown")))) -> Young Adult
A39: U1038 | B39: San Luis Potosi | C39: San Luis Potosi | D39: Mexico | E39: 22.125786 | F39: -100.9437 | G39: Yes | H39: Social Drinker | I39: Public | J39: Single | K39: Independent | L39: 82 | M39: Student | N39: Low | O39: Mexican | P39: =IF(L39<=12,"Children", IF(L39<=19,"Teenagers", IF(L39<=49,"Young Adult", IF(L39>=50,"Old","Unknown")))) -> Old
A40: U1039 | B40: Ciudad Victoria | C40: Tamaulipas | D40: Mexico | E40: 23.738067 | F40: -99.139906 | G40: No | H40: Social Drinker | J40: Single | K40: Independent | L40: 23 | M40: Student | N40: Medium | O40: Regional | P40: =IF(L40<=12,"Children", IF(L40<=19,"Teenagers", IF(L40<=49,"Young Adult", IF(L40>=50,"Old","Unknown")))) -> Young Adult
A41: U1040 | B41: Cuernavaca | C41: Morelos | D41: Mexico | E41: 18.895187 | F41: -99.18039 | G41: No | H41: Abstemious | I41: Public | J41: Single | K41: Independent | L41: 18 | M41: Student | N41: Medium | O41: Pizzeria | P41: =IF(L41<=12,"Children", IF(L41<=19,"Teenagers", IF(L41<=49,"Young Adult", IF(L41>=50,"Old","Unknown")))) -> Teenagers
A42: U1041 | B42: Cuernavaca | C42: Morelos | D42: Mexico | E42: 18.935191 | F42: -99.23624 | G42: No | H42: Abstemious | I42: On Foot | J42: Single | K42: Independent | L42: 27 | M42: Employed | N42: Medium | O42: Contemporary | P42: =IF(L42<=12,"Children", IF(L42<=19,"Teenagers", IF(L42<=49,"Young Adult", IF(L42>=50,"Old","Unknown")))) -> Young Adult
A43: U1042 | B43: Cuernavaca | C43: Morelos | D43: Mexico | E43: 18.925773 | F43: -99.219589 | G43: No | H43: Abstemious | I43: Car | J43: Single | K43: Independent | L43: 69 | M43: Student | N43: High | O43: Mexican | P43: =IF(L43<=12,"Children", IF(L43<=19,"Teenagers", IF(L43<=49,"Young Adult", IF(L43>=50,"Old","Unknown")))) -> Old
...

Sheet consumers
A1: Consumer_ID | B1: Consumer_City | C1: Consumer_State | D1: Consumer_Country | E1: Consumer_Latitude | F1: Consumer_Longitude | G1: Consumer_Smoker | H1: Consumer_Drink_Level | I1: Consumer_Transportation_Method | J1: Consumer_Marital_Status | K1: Consumer_Children | L1: Consumer_Age | M1: Consumer_Occupation | N1: Consumer_Budget | O1: Preferred_Cuisine
A2: U1001 | B2: San Luis Potosi | C2: San Luis Potosi | D2: Mexico | E2: 22.139997 | F2: -100.9788 | G2: No | H2: Abstemious | I2: On Foot | J2: Single | K2: Independent | L2: 23 | M2: Student | N2: Medium | O2: =_xlfn.XLOOKUP(A2, consumer_preferences!A:A, consumer_preferences!B:B, "Not Found") -> American
A3: U1002 | B3: San Luis Potosi | C3: San Luis Potosi | D3: Mexico | E3: 22.150087 | F3: -100.98332 | G3: No | H3: Abstemious | I3: Public | J3: Single | K3: Independent | L3: 22 | M3: Student | N3: Low | O3: =_xlfn.XLOOKUP(A3, consumer_preferences!A:A, consumer_preferences!B:B, "Not Found") -> Mexican
A4: U1003 | B4: San Luis Potosi | C4: San Luis Potosi | D4: Mexico | E4: 22.119847 | F4: -100.94653 | G4: No | H4: Social Drinker | I4: Public | J4: Single | K4: Independent | L4: 23 | M4: Student | N4: Low | O4: =_xlfn.XLOOKUP(A4, consumer_preferences!A:A, consumer_preferences!B:B, "Not Found") -> Mexican
A5: U1004 | B5: Cuernavaca | C5: Morelos | D5: Mexico | E5: 18.867 | F5: -99.183 | G5: No | H5: Abstemious | I5: Public | J5: Single | K5: Independent | L5: 72 | M5: Employed | N5: Medium | O5: =_xlfn.XLOOKUP(A5, consumer_preferences!A:A, consumer_preferences!B:B, "Not Found") -> Bakery
A6: U1005 | B6: San Luis Potosi | C6: San Luis Potosi | D6: Mexico | E6: 22.183477 | F6: -100.95989 | G6: No | H6: Abstemious | I6: Public | J6: Single | K6: Independent | L6: 20 | M6: Student | N6: Medium | O6: =_xlfn.XLOOKUP(A6, consumer_preferences!A:A, consumer_preferences!B:B, "Not Found") -> American
A7: U1006 | B7: San Luis Potosi | C7: San Luis Potosi | D7: Mexico | E7: 22.15 | F7: -100.983 | G7: Yes | H7: Social Drinker | I7: Car | J7: Single | K7: Independent | L7: 23 | M7: Student | N7: Medium | O7: =_xlfn.XLOOKUP(A7, consumer_preferences!A:A, consumer_preferences!B:B, "Not Found") -> Mexican
A8: U1007 | B8: San Luis Potosi | C8: San Luis Potosi | D8: Mexico | E8: 22.118464 | F8: -100.93826 | G8: No | H8: Casual Drinker | I8: Public | J8: Single | K8: Independent | L8: 23 | M8: Student | N8: Low | O8: =_xlfn.XLOOKUP(A8, consumer_preferences!A:A, consumer_preferences!B:B, "Not Found") -> Family
A9: U1008 | B9: San Luis Potosi | C9: San Luis Potosi | D9: Mexico | E9: 22.122989 | F9: -100.92381 | G9: No | H9: Social Drinker | I9: Public | J9: Single | K9: Independent | L9: 23 | M9: Student | N9: Low | O9: =_xlfn.XLOOKUP(A9, consumer_preferences!A:A, consumer_preferences!B:B, "Not Found") -> Coffee Shop
A10: U1009 | B10: San Luis Potosi | C10: San Luis Potosi | D10: Mexico | E10: 22.159427 | F10: -100.99045 | G10: No | H10: Abstemious | I10: On Foot | J10: Single | K10: Kids | L10: 21 | M10: Student | N10: Medium | O10: =_xlfn.XLOOKUP(A10, consumer_preferences!A:A, consumer_preferences!B:B, "Not Found") -> Diner
A11: U1010 | B11: San Luis Potosi | C11: San Luis Potosi | D11: Mexico | E11: 22.190889 | F11: -100.99867 | G11: No | H11: Social Drinker | I11: Car | J11: Married | K11: Kids | L11: 25 | M11: Student | N11: Medium | O11: =_xlfn.XLOOKUP(A11, consumer_preferences!A:A, consumer_preferences!B:B, "Not Found") -> Mexican
A12: U1011 | B12: Ciudad Victoria | C12: Tamaulipas | D12: Mexico | E12: 23.724972 | F12: -99.152856 | G12: No | H12: Abstemious | I12: Public | J12: Single | K12: Independent | L12: 23 | M12: Student | N12: Medium | O12: =_xlfn.XLOOKUP(A12, consumer_preferences!A:A, consumer_preferences!B:B, "Not Found") -> Mexican
A13: U1012 | B13: Cuernavaca | C13: Morelos | D13: Mexico | E13: 18.813348 | F13: -99.243697 | G13: No | H13: Casual Drinker | I13: Public | J13: Single | K13: Independent | L13: 24 | M13: Student | N13: Medium | O13: =_xlfn.XLOOKUP(A13, consumer_preferences!A:A, consumer_preferences!B:B, "Not Found") -> Latin American
... A17: U1016 | B17: San Luis Potosi | C17: San Luis Potosi | D17: Mexico | E17: 22.156247 | F17: -100.9774 | G17: No | H17: Casual Drinker | I17: On Foot | J17: Single | K17: Independent | L17: 21 | M17: Student | N17: Medium | O17: =_xlfn.XLOOKUP(A17, consumer_preferences!A:A, consumer_preferences!B:B, "Not Found") -> Coffee Shop
A18: U1017 | B18: Cuernavaca | C18: Morelos | D18: Mexico | E18: 18.952615 | F18: -99.201616 | G18: No | H18: Casual Drinker | I18: Public | J18: Single | L18: 21 | M18: Employed | N18: Medium | O18: =_xlfn.XLOOKUP(A18, consumer_preferences!A:A, consumer_preferences!B:B, "Not Found") -> Chinese
A19: U1018 | B19: San Luis Potosi | C19: San Luis Potosi | D19: Mexico | E19: 22.190949 | F19: -100.9179 | G19: Yes | H19: Casual Drinker | I19: Public | J19: Single | K19: Independent | L19: 23 | M19: Student | N19: Low | O19: =_xlfn.XLOOKUP(A19, consumer_preferences!A:A, consumer_preferences!B:B, "Not Found") -> Mexican
A20: U1019 | B20: San Luis Potosi | C20: San Luis Potosi | D20: Mexico | E20: 22.153385 | F20: -100.97529 | G20: No | H20: Casual Drinker | I20: Public | J20: Single | K20: Independent | L20: 23 | M20: Student | N20: Medium | O20: =_xlfn.XLOOKUP(A20, consumer_preferences!A:A, consumer_preferences!B:B, "Not Found") -> Family
A21: U1020 | B21: Cuernavaca | C21: Morelos | D21: Mexico | E21: 18.878189 | F21: -99.222969 | G21: No | H21: Abstemious | I21: Public | J21: Single | K21: Independent | L21: 30 | M21: Employed | N21: Medium | O21: =_xlfn.XLOOKUP(A21, consumer_preferences!A:A, consumer_preferences!B:B, "Not Found") -> Mexican
A22: U1021 | B22: Ciudad Victoria | C22: Tamaulipas | D22: Mexico | E22: 23.730569 | F22: -99.171883 | G22: No | H22: Social Drinker | I22: Car | J22: Single | K22: Dependent | L22: 28 | M22: Student | N22: Medium | O22: =_xlfn.XLOOKUP(A22, consumer_preferences!A:A, consumer_preferences!B:B, "Not Found") -> Pizzeria
A23: U1022 | B23: San Luis Potosi | C23: San Luis Potosi | D23: Mexico | E23: 22.146708 | F23: -100.96435 | G23: No | H23: Casual Drinker | I23: Car | J23: Single | K23: Independent | L23: 22 | M23: Student | N23: Medium | O23: =_xlfn.XLOOKUP(A23, consumer_preferences!A:A, consumer_preferences!B:B, "Not Found") -> Mexican
A24: U1023 | B24: Ciudad Victoria | C24: Tamaulipas | D24: Mexico | E24: 23.752943 | F24: -99.166589 | G24: No | H24: Casual Drinker | I24: Car | J24: Single | K24: Independent | L24: 24 | M24: Student | N24: Low | O24: =_xlfn.XLOOKUP(A24, consumer_preferences!A:A, consumer_preferences!B:B, "Not Found") -> Mexican
A25: U1024 | B25: San Luis Potosi | C25: San Luis Potosi | D25: Mexico | E25: 22.154021 | F25: -100.97603 | H25: Abstemious | L25: 82 | O25: =_xlfn.XLOOKUP(A25, consumer_preferences!A:A, consumer_preferences!B:B, "Not Found") -> Afghan
A26: U1025 | B26: San Luis Potosi | C26: San Luis Potosi | D26: Mexico | E26: 22.125603 | F26: -100.90784 | G26: No | H26: Social Drinker | I26: Public | J26: Single | L26: 22 | M26: Student | N26: Medium | O26: =_xlfn.XLOOKUP(A26, consumer_preferences!A:A, consumer_preferences!B:B, "Not Found") -> Mexican
A27: U1026 | B27: Ciudad Victoria | C27: Tamaulipas | D27: Mexico | E27: 23.733 | F27: -99.133 | G27: No | H27: Abstemious | I27: Public | J27: Single | K27: Independent | L27: 23 | M27: Student | N27: Medium | O27: =_xlfn.XLOOKUP(A27, consumer_preferences!A:A, consumer_preferences!B:B, "Not Found") -> Mexican
A28: U1027 | B28: San Luis Potosi | C28: San Luis Potosi | D28: Mexico | E28: 22.16515 | F28: -100.98701 | G28: Yes | H28: Social Drinker | I28: Public | J28: Single | K28: Independent | L28: 23 | M28: Student | N28: Low | O28: =_xlfn.XLOOKUP(A28, consumer_preferences!A:A, consumer_preferences!B:B, "Not Found") -> Family
A29: U1028 | B29: Ciudad Victoria | C29: Tamaulipas | D29: Mexico | E29: 23.752874 | F29: -99.169242 | G29: No | H29: Abstemious | I29: Public | J29: Single | K29: Independent | L29: 23 | M29: Student | N29: Medium | O29: =_xlfn.XLOOKUP(A29, consumer_preferences!A:A, consumer_preferences!B:B, "Not Found") -> Mexican
A30: U1029 | B30: San Luis Potosi | C30: San Luis Potosi | D30: Mexico | E30: 22.151796 | F30: -100.98907 | G30: Yes | H30: Casual Drinker | I30: Public | J30: Single | K30: Independent | L30: 22 | M30: Student | N30: Low | O30: =_xlfn.XLOOKUP(A30, consumer_preferences!A:A, consumer_preferences!B:B, "Not Found") -> Mexican
A31: U1030 | B31: Cuernavaca | C31: Morelos | D31: Mexico | E31: 18.844818 | F31: -99.182758 | G31: No | H31: Casual Drinker | I31: On Foot | J31: Single | K31: Independent | L31: 21 | M31: Student | N31: Medium | O31: =_xlfn.XLOOKUP(A31, consumer_preferences!A:A, consumer_preferences!B:B, "Not Found") -> Mexican
A32: U1031 | B32: Ciudad Victoria | C32: Tamaulipas | D32: Mexico | E32: 23.735698 | F32: -99.159851 | G32: No | H32: Abstemious | J32: Married | K32: Kids | L32: 20 | M32: Unemployed | N32: Medium | O32: =_xlfn.XLOOKUP(A32, consumer_preferences!A:A, consumer_preferences!B:B, "Not Found") -> Mexican
A33: U1032 | B33: San Luis Potosi | C33: San Luis Potosi | D33: Mexico | E33: 22.169184 | F33: -100.98684 | G33: No | H33: Abstemious | I33: Public | J33: Single | K33: Independent | L33: 23 | M33: Student | N33: Medium | O33: =_xlfn.XLOOKUP(A33, consumer_preferences!A:A, consumer_preferences!B:B, "Not Found") -> Mexican
A34: U1033 | B34: San Luis Potosi | C34: San Luis Potosi | D34: Mexico | E34: 22.15 | F34: -100.983 | G34: No | H34: Social Drinker | I34: On Foot | J34: Single | L34: 21 | M34: Student | N34: Low | O34: =_xlfn.XLOOKUP(A34, consumer_preferences!A:A, consumer_preferences!B:B, "Not Found") -> Mexican
A35: U1034 | B35: San Luis Potosi | C35: San Luis Potosi | D35: Mexico | E35: 22.137178 | F35: -101.01317 | G35: No | H35: Casual Drinker | I35: Public | J35: Single | K35: Independent | L35: 22 | M35: Student | N35: Medium | O35: =_xlfn.XLOOKUP(A35, consumer_preferences!A:A, consumer_preferences!B:B, "Not Found") -> Mexican
A36: U1035 | B36: Cuernavaca | C36: Morelos | D36: Mexico | E36: 18.839671 | F36: -99.223897 | G36: Yes | H36: Casual Drinker | I36: Car | J36: Single | K36: Independent | L36: 27 | M36: Student | N36: Medium | O36: =_xlfn.XLOOKUP(A36, consumer_preferences!A:A, consumer_preferences!B:B, "Not Found") -> Family
A37: U1036 | B37: San Luis Potosi | C37: San Luis Potosi | D37: Mexico | E37: 22.160572 | F37: -100.98942 | G37: No | H37: Social Drinker | I37: Public | J37: Single | K37: Independent | L37: 21 | M37: Student | N37: Medium | O37: =_xlfn.XLOOKUP(A37, consumer_preferences!A:A, consumer_preferences!B:B, "Not Found") -> Mexican
A38: U1037 | B38: San Luis Potosi | C38: San Luis Potosi | D38: Mexico | E38: 22.15031 | F38: -100.90054 | G38: No | H38: Social Drinker | I38: Public | J38: Single | K38: Independent | L38: 22 | M38: Student | N38: Low | O38: =_xlfn.XLOOKUP(A38, consumer_preferences!A:A, consumer_preferences!B:B, "Not Found") -> Mexican
A39: U1038 | B39: San Luis Potosi | C39: San Luis Potosi | D39: Mexico | E39: 22.125786 | F39: -100.9437 | G39: Yes | H39: Social Drinker | I39: Public | J39: Single | K39: Independent | L39: 82 | M39: Student | N39: Low | O39: =_xlfn.XLOOKUP(A39, consumer_preferences!A:A, consumer_preferences!B:B, "Not Found") -> Mexican
A40: U1039 | B40: Ciudad Victoria | C40: Tamaulipas | D40: Mexico | E40: 23.738067 | F40: -99.139906 | G40: No | H40: Social Drinker | J40: Single | K40: Independent | L40: 23 | M40: Student | N40: Medium | O40: =_xlfn.XLOOKUP(A40, consumer_preferences!A:A, consumer_preferences!B:B, "Not Found") -> Regional
A41: U1040 | B41: Cuernavaca | C41: Morelos | D41: Mexico | E41: 18.895187 | F41: -99.18039 | G41: No | H41: Abstemious | I41: Public | J41: Single | K41: Independent | L41: 18 | M41: Student | N41: Medium | O41: =_xlfn.XLOOKUP(A41, consumer_preferences!A:A, consumer_preferences!B:B, "Not Found") -> Pizzeria
A42: U1041 | B42: Cuernavaca | C42: Morelos | D42: Mexico | E42: 18.935191 | F42: -99.23624 | G42: No | H42: Abstemious | I42: On Foot | J42: Single | K42: Independent | L42: 27 | M42: Employed | N42: Medium | O42: =_xlfn.XLOOKUP(A42, consumer_preferences!A:A, consumer_preferences!B:B, "Not Found") -> Contemporary
A43: U1042 | B43: Cuernavaca | C43: Morelos | D43: Mexico | E43: 18.925773 | F43: -99.219589 | G43: No | H43: Abstemious | I43: Car | J43: Single | K43: Independent | L43: 69 | M43: Student | N43: High | O43: =_xlfn.XLOOKUP(A43, consumer_preferences!A:A, consumer_preferences!B:B, "Not Found") -> Mexican
...

Sheet RatingsTable
A1: Consumer_ID | B1: Restaurant_ID | C1: Overall_Rating | D1: Food_Rating | E1: Service_Rating
A2: U1077 | B2: 135085 | C2: 2 | D2: 2 | E2: 2
A3: U1077 | B3: 135038 | C3: 2 | D3: 2 | E3: 1
A4: U1077 | B4: 132825 | C4: 2 | D4: 2 | E4: 2
A5: U1077 | B5: 135060 | C5: 1 | D5: 2 | E5: 2
A6: U1068 | B6: 135104 | C6: 1 | D6: 1 | E6: 2
A7: U1068 | B7: 132740 | C7: 0 | D7: 0 | E7: 0
A8: U1068 | B8: 132663 | C8: 1 | D8: 1 | E8: 1
A9: U1068 | B9: 132732 | C9: 0 | D9: 0 | E9: 0
A10: U1068 | B10: 132630 | C10: 1 | D10: 1 | E10: 1
A11: U1067 | B11: 132584 | C11: 2 | D11: 2 | E11: 2
A12: U1067 | B12: 132733 | C12: 1 | D12: 1 | E12: 1
A13: U1067 | B13: 132732 | C13: 1 | D13: 2 | E13: 2
... A1162: U1068 | B1162: 132660 | C1162: 0 | D1162: 0 | E1162: 0

Sheet ratings
A1: Consumer_ID | B1: Restaurant_ID | C1: Overall_Rating | D1: Food_Rating | E1: Service_Rating
A2: U1077 | B2: 135085 | C2: 2 | D2: 2 | E2: 2
A3: U1077 | B3: 135038 | C3: 2 | D3: 2 | E3: 1
A4: U1077 | B4: 132825 | C4: 2 | D4: 2 | E4: 2
A5: U1077 | B5: 135060 | C5: 1 | D5: 2 | E5: 2
A6: U1068 | B6: 135104 | C6: 1 | D6: 1 | E6: 2
A7: U1068 | B7: 132740 | C7: 0 | D7: 0 | E7: 0
A8: U1068 | B8: 132663 | C8: 1 | D8: 1 | E8: 1
A9: U1068 | B9: 132732 | C9: 0 | D9: 0 | E9: 0
A10: U1068 | B10: 132630 | C10: 1 | D10: 1 | E10: 1
A11: U1067 | B11: 132584 | C11: 2 | D11: 2 | E11: 2
A12: U1067 | B12: 132733 | C12: 1 | D12: 1 | E12: 1
A13: U1067 | B13: 132732 | C13: 1 | D13: 2 | E13: 2
... A1162: U1068 | B1162: 132660 | C1162: 0 | D1162: 0 | E1162: 0

Sheet RestaurantTable
A1: Restaurant_ID | B1: Restaurant_Name | C1: Restaurant_City | D1: Restaurant_State | E1: Restaurant_Country | F1: Restaurant_Zip_Code | G1: Restaurant_Latitude | H1: Restaurant_Longitude | I1: Restaurant_Alcohol_Service | J1: Restaurant_Smoking_Allowed | K1: Restaurant_Price | L1: Restaurant_Franchise | M1: Restaurant_Area | N1: Restaurant_Parking | O1: Restaurant_Cuisine
A2: 132560 | B2: Puesto de Gorditas | C2: Ciudad Victoria | D2: Tamaulipas | E2: Mexico | G2: 23.752304 | H2: -99.166913 | I2: None | J2: Yes | K2: Low | L2: No | M2: Open | N2: Public | O2: Regional
A3: 132561 | B3: Cafe Ambar | C3: Ciudad Victoria | D3: Tamaulipas | E3: Mexico | G3: 23.726819 | H3: -99.126506 | I3: None | J3: No | K3: Low | L3: No | M3: Closed | N3: None | O3: Not Found
A4: 132564 | B4: Church's | C4: Ciudad Victoria | D4: Tamaulipas | E4: Mexico | G4: 23.730925 | H4: -99.145185 | I4: None | J4: No | K4: Low | L4: No | M4: Closed | N4: None | O4: Not Found
A5: 132572 | B5: Cafe Chaires | C5: San Luis Potosi | D5: San Luis Potosi | E5: Mexico | G5: 22.141647 | H5: -100.99271 | I5: None | J5: No | K5: Low | L5: No | M5: Closed | N5: Yes | O5: Cafeteria
A6: 132583 | B6: McDonalds Centro | C6: Cuernavaca | D6: Morelos | E6: Mexico | F6: 62000 | G6: 18.92229 | H6: -99.234332 | I6: None | J6: No | K6: Low | L6: Yes | M6: Closed | N6: None | O6: American
A7: 132584 | B7: Gorditas Doña Tota | C7: Ciudad Victoria | D7: Tamaulipas | E7: Mexico | G7: 23.752365 | H7: -99.165288 | I7: None | J7: No | K7: Medium | L7: Yes | M7: Closed | N7: Yes | O7: Mexican
A8: 132594 | B8: Tacos De Barbacoa Enfrente Del Tec | C8: Ciudad Victoria | D8: Tamaulipas | E8: Mexico | G8: 23.752168 | H8: -99.165709 | I8: None | J8: No | K8: Low | L8: No | M8: Open | N8: Public | O8: Mexican
A9: 132608 | B9: Hamburguesas La Perica | C9: Ciudad Victoria | D9: Tamaulipas | E9: Mexico | G9: 23.758805 | H9: -99.16513 | I9: None | J9: Yes | K9: Low | L9: Yes | M9: Open | N9: Public | O9: Mexican
A10: 132609 | B10: Pollo Frito Buenos Aires | C10: Ciudad Victoria | D10: Tamaulipas | E10: Mexico | G10: 23.760268 | H10: -99.165865 | I10: None | J10: No | K10: Low | L10: Yes | M10: Closed | N10: Yes | O10: Fast Food
A11: 132613 | B11: Carnitas Mata | C11: Ciudad Victoria | D11: Tamaulipas | E11: Mexico | G11: 23.752903 | H11: -99.165076 | I11: None | J11: Yes | K11: Medium | L11: Yes | M11: Closed | N11: Yes | O11: Mexican
A12: 132626 | B12: La Perica Hamburguesa | C12: Ciudad Victoria | D12: Tamaulipas | E12: Mexico | G12: 23.737583 | H12: -99.135132 | I12: None | J12: No | K12: Medium | L12: Yes | M12: Closed | N12: Yes | O12: Italian
A13: 132630 | B13: Palomo Tec | C13: Ciudad Victoria | D13: Tamaulipas | E13: Mexico | G13: 23.752931 | H13: -99.164473 | I13: None | J13: No | K13: Low | L13: No | M13: Closed | N13: None | O13: Mexican
A14: 132654 | B14: Carnitas Mata Calle 16 de Septiembre | C14: Ciudad Victoria | D14: Tamaulipas | E14: Mexico | G14: 23.735523 | H14: -99.129588 | I14: None | J14: No | K14: Low | L14: No | M14: Closed | N14: None | O14: Not Found
A15: 132660 | B15: Carnitas Mata Calle Emilio Portes Gil | C15: Ciudad Victoria | D15: Tamaulipas | E15: Mexico | G15: 23.752943 | H15: -99.164679 | I15: None | J15: No | K15: Low | L15: No | M15: Closed | N15: None | O15: Not Found
A16: 132663 | B16: Tacos Abi | C16: Ciudad Victoria | D16: Tamaulipas | E16: Mexico | G16: 23.752511 | H16: -99.166954 | I16: None | J16: No | K16: Low | L16: No | M16: Closed | N16: None | O16: Mexican
A17: 132665 | B17: Tacos Correcaminos | C17: Ciudad Victoria | D17: Tamaulipas | E17: Mexico | G17: 23.736798 | H17: -99.134241 | I17: None | J17: No | K17: Low | L17: No | M17: Closed | N17: None | O17: Mexican
A18: 132667 | B18: Little Pizza Emilio Portes Gil | C18: Ciudad Victoria | D18: Tamaulipas | E18: Mexico | G18: 23.752697 | H18: -99.163359 | I18: None | J18: No | K18: Low | L18: Yes | M18: Closed | N18: None | O18: Armenian
... A23: 132723 | B23: Gordas De Morales | C23: San Luis Potosi | D23: San Luis Potosi | E23: Mexico | G23: 22.148934 | H23: -101.01985 | I23: Full Bar | J23: Smoking Section | K23: Medium | L23: No | M23: Closed | N23: Public | O23: Mexican
A24: 132732 | B24: Taqueria El Amigo | C24: Ciudad Victoria | D24: Tamaulipas | E24: Mexico | F24: 87018 | G24: 23.754357 | H24: -99.171288 | I24: None | J24: No | K24: Low | L24: No | M24: Open | N24: None | O24: Mexican
A25: 132733 | B25: Little Caesars | C25: Ciudad Victoria | D25: Tamaulipas | E25: Mexico | G25: 23.752707 | H25: -99.162565 | I25: None | J25: No | K25: Medium | L25: Yes | M25: Closed | N25: Yes | O25: Pizzeria
A26: 132740 | B26: Carreton De Flautas Y Migadas | C26: Ciudad Victoria | D26: Tamaulipas | E26: Mexico | G26: 23.752197 | H26: -99.166632 | I26: None | J26: Yes | K26: Low | L26: No | M26: Open | N26: None | O26: Mexican
A27: 132754 | B27: Cabana Huasteca | C27: San Luis Potosi | D27: San Luis Potosi | E27: Mexico | G27: 22.147738 | H27: -100.99062 | I27: None | J27: No | K27: Medium | L27: No | M27: Closed | N27: None | O27: Mexican
A28: 132755 | B28: La Estrella De Dimas | C28: San Luis Potosi | D28: San Luis Potosi | E28: Mexico | G28: 22.153324 | H28: -101.01955 | I28: None | J28: No | K28: Medium | L28: No | M28: Closed | N28: Public | O28: Mexican
A29: 132766 | B29: Mikasa | C29: Cuernavaca | D29: Morelos | E29: Mexico | G29: 18.910178 | H29: -99.231544 | I29: Wine & Beer | J29: No | K29: Medium | L29: No | M29: Closed | N29: Yes | O29: Japanese
A30: 132767 | B30: Restaurant Familiar El Chino | C30: Jiutepec | D30: Morelos | E30: Mexico | G30: 18.882087 | H30: -99.163027 | I30: Wine & Beer | J30: Yes | K30: Medium | L30: No | M30: Open | N30: Yes | O30: Vietnamese
A31: 132768 | B31: Mariscos Tia Licha | C31: Cuernavaca | D31: Morelos | E31: Mexico | F31: 62320 | G31: 18.925773 | H31: -99.232636 | I31: None | J31: No | K31: Medium | L31: Yes | M31: Closed | N31: None | O31: Family
A32: 132773 | B32: El Cotorreo | C32: Cuernavaca | D32: Morelos | E32: Mexico | G32: 18.869993 | H32: -99.210319 | I32: Wine & Beer | J32: Yes | K32: Low | L32: No | M32: Open | N32: None | O32: Family
A33: 132825 | B33: Puesto De Tacos | C33: San Luis Potosi | D33: San Luis Potosi | E33: Mexico | F33: 78280 | G33: 22.147392 | H33: -100.98309 | I33: None | J33: No | K33: Low | L33: No | M33: Open | N33: None | O33: Mexican
A34: 132830 | B34: Rincon Huasteco | C34: San Luis Potosi | D34: San Luis Potosi | E34: Mexico | G34: 22.150849 | H34: -100.93975 | I34: None | J34: No | K34: Low | L34: No | M34: Closed | N34: None | O34: Not Found
A35: 132834 | B35: Gorditas Doa Gloria | C35: San Luis Potosi | D35: San Luis Potosi | E35: Mexico | F35: 78349 | G35: 22.156469 | H35: -100.98554 | I35: None | J35: No | K35: Low | L35: No | M35: Closed | N35: Public | O35: Mexican
A36: 132845 | B36: Cenaduria El Rincón De Tlaquepaque | C36: San Luis Potosi | D36: San Luis Potosi | E36: Mexico | G36: 22.126293 | H36: -100.90078 | I36: None | J36: No | K36: Medium | L36: No | M36: Closed | N36: None | O36: Mexican
A37: 132846 | B37: El Lechon Potosino | C37: San Luis Potosi | D37: San Luis Potosi | E37: Mexico | G37: 22.142273 | H37: -100.94265 | I37: None | J37: Yes | K37: Low | L37: No | M37: Open | N37: None | O37: International
A38: 132847 | B38: Don Burguers | C38: San Luis Potosi | D38: San Luis Potosi | E38: Mexico | G38: 22.144337 | H38: -100.93738 | I38: None | J38: No | K38: Low | L38: No | M38: Open | N38: None | O38: Not Found
A39: 132851 | B39: KFC | C39: San Luis Potosi | D39: San Luis Potosi | E39: Mexico | G39: 22.136872 | H39: -100.93457 | I39: None | J39: No | K39: Low | L39: No | M39: Closed | N39: Yes | O39: American
A40: 132854 | B40: Sirlone | C40: San Luis Potosi | D40: San Luis Potosi | E40: Mexico | G40: 22.137863 | H40: -100.93833 | I40: Wine & Beer | J40: No | K40: Medium | L40: No | M40: Closed | N40: Yes | O40: International
A41: 132856 | B41: Unicol's Pizza | C41: San Luis Potosi | D41: San Luis Potosi | E41: Mexico | G41: 22.151378 | H41: -100.97463 | I41: Wine & Beer | J41: No | K41: Low | L41: No | M41: Closed | N41: None | O41: Italian
A42: 132858 | B42: Hamburguesas Valle Dorado | C42: San Luis Potosi | D42: San Luis Potosi | E42: Mexico | G42: 22.131292 | H42: -100.93719 | I42: None | J42: No | K42: Low | L42: No | M42: Closed | N42: None | O42: Burgers
A43: 132861 | B43: Carl's Jr | C43: San Luis Potosi | D43: San Luis Potosi | E43: Mexico | G43: 22.148097 | H43: -101.0173 | I43: None | J43: No | K43: Medium | L43: Yes | M43: Closed | N43: Yes | O43: Burgers
A44: 132862 | B44: La Posada Del Virrey | C44: San Luis Potosi | D44: San Luis Potosi | E44: Mexico | G44: 22.150643 | H44: -100.98701 | I44: Wine & Beer | J44: No | K44: High | L44: No | M44: Closed | N44: Valet | O44: International
...

Sheet restaurants
A1: Restaurant_ID | B1: Restaurant_Name | C1: Restaurant_City | D1: Restaurant_State | E1: Restaurant_Country | F1: Restaurant_Zip_Code | G1: Restaurant_Latitude | H1: Restaurant_Longitude | I1: Restaurant_Alcohol_Service | J1: Restaurant_Smoking_Allowed | K1: Restaurant_Price | L1: Restaurant_Franchise | M1: Restaurant_Area | N1: Restaurant_Parking | O1: Restaurant_Cuisine
A2: 132560 | B2: Puesto de Gorditas | C2: Ciudad Victoria | D2: Tamaulipas | E2: Mexico | G2: 23.752304 | H2: -99.166913 | I2: None | J2: Yes | K2: Low | L2: No | M2: Open | N2: Public | O2: =_xlfn.XLOOKUP(A2, restaurant_cuisines!A:A,restaurant_cuisines!B:B,"Not Found") -> Regional
A3: 132561 | B3: Cafe Ambar | C3: Ciudad Victoria | D3: Tamaulipas | E3: Mexico | G3: 23.726819 | H3: -99.126506 | I3: None | J3: No | K3: Low | L3: No | M3: Closed | N3: None | O3: =_xlfn.XLOOKUP(A3, restaurant_cuisines!A:A,restaurant_cuisines!B:B,"Not Found") -> Not Found
A4: 132564 | B4: Church's | C4: Ciudad Victoria | D4: Tamaulipas | E4: Mexico | G4: 23.730925 | H4: -99.145185 | I4: None | J4: No | K4: Low | L4: No | M4: Closed | N4: None | O4: =_xlfn.XLOOKUP(A4, restaurant_cuisines!A:A,restaurant_cuisines!B:B,"Not Found") -> Not Found
A5: 132572 | B5: Cafe Chaires | C5: San Luis Potosi | D5: San Luis Potosi | E5: Mexico | G5: 22.141647 | H5: -100.99271 | I5: None | J5: No | K5: Low | L5: No | M5: Closed | N5: Yes | O5: =_xlfn.XLOOKUP(A5, restaurant_cuisines!A:A,restaurant_cuisines!B:B,"Not Found") -> Cafeteria
A6: 132583 | B6: McDonalds Centro | C6: Cuernavaca | D6: Morelos | E6: Mexico | F6: 62000 | G6: 18.92229 | H6: -99.234332 | I6: None | J6: No | K6: Low | L6: Yes | M6: Closed | N6: None | O6: =_xlfn.XLOOKUP(A6, restaurant_cuisines!A:A,restaurant_cuisines!B:B,"Not Found") -> American
A7: 132584 | B7: Gorditas Doña Tota | C7: Ciudad Victoria | D7: Tamaulipas | E7: Mexico | G7: 23.752365 | H7: -99.165288 | I7: None | J7: No | K7: Medium | L7: Yes | M7: Closed | N7: Yes | O7: =_xlfn.XLOOKUP(A7, restaurant_cuisines!A:A,restaurant_cuisines!B:B,"Not Found") -> Mexican
A8: 132594 | B8: Tacos De Barbacoa Enfrente Del Tec | C8: Ciudad Victoria | D8: Tamaulipas | E8: Mexico | G8: 23.752168 | H8: -99.165709 | I8: None | J8: No | K8: Low | L8: No | M8: Open | N8: Public | O8: =_xlfn.XLOOKUP(A8, restaurant_cuisines!A:A,restaurant_cuisines!B:B,"Not Found") -> Mexican
A9: 132608 | B9: Hamburguesas La Perica | C9: Ciudad Victoria | D9: Tamaulipas | E9: Mexico | G9: 23.758805 | H9: -99.16513 | I9: None | J9: Yes | K9: Low | L9: Yes | M9: Open | N9: Public | O9: =_xlfn.XLOOKUP(A9, restaurant_cuisines!A:A,restaurant_cuisines!B:B,"Not Found") -> Mexican
A10: 132609 | B10: Pollo Frito Buenos Aires | C10: Ciudad Victoria | D10: Tamaulipas | E10: Mexico | G10: 23.760268 | H10: -99.165865 | I10: None | J10: No | K10: Low | L10: Yes | M10: Closed | N10: Yes | O10: =_xlfn.XLOOKUP(A10, restaurant_cuisines!A:A,restaurant_cuisines!B:B,"Not Found") -> Fast Food
A11: 132613 | B11: Carnitas Mata | C11: Ciudad Victoria | D11: Tamaulipas | E11: Mexico | G11: 23.752903 | H11: -99.165076 | I11: None | J11: Yes | K11: Medium | L11: Yes | M11: Closed | N11: Yes | O11: =_xlfn.XLOOKUP(A11, restaurant_cuisines!A:A,restaurant_cuisines!B:B,"Not Found") -> Mexican
A12: 132626 | B12: La Perica Hamburguesa | C12: Ciudad Victoria | D12: Tamaulipas | E12: Mexico | G12: 23.737583 | H12: -99.135132 | I12: None | J12: No | K12: Medium | L12: Yes | M12: Closed | N12: Yes | O12: =_xlfn.XLOOKUP(A12, restaurant_cuisines!A:A,restaurant_cuisines!B:B,"Not Found") -> Italian
A13: 132630 | B13: Palomo Tec | C13: Ciudad Victoria | D13: Tamaulipas | E13: Mexico | G13: 23.752931 | H13: -99.164473 | I13: None | J13: No | K13: Low | L13: No | M13: Closed | N13: None | O13: =_xlfn.XLOOKUP(A13, restaurant_cuisines!A:A,restaurant_cuisines!B:B,"Not Found") -> Mexican
A14: 132654 | B14: Carnitas Mata Calle 16 de Septiembre | C14: Ciudad Victoria | D14: Tamaulipas | E14: Mexico | G14: 23.735523 | H14: -99.129588 | I14: None | J14: No | K14: Low | L14: No | M14: Closed | N14: None | O14: =_xlfn.XLOOKUP(A14, restaurant_cuisines!A:A,restaurant_cuisines!B:B,"Not Found") -> Not Found
A15: 132660 | B15: Carnitas Mata Calle Emilio Portes Gil | C15: Ciudad Victoria | D15: Tamaulipas | E15: Mexico | G15: 23.752943 | H15: -99.164679 | I15: None | J15: No | K15: Low | L15: No | M15: Closed | N15: None | O15: =_xlfn.XLOOKUP(A15, restaurant_cuisines!A:A,restaurant_cuisines!B:B,"Not Found") -> Not Found
A16: 132663 | B16: Tacos Abi | C16: Ciudad Victoria | D16: Tamaulipas | E16: Mexico | G16: 23.752511 | H16: -99.166954 | I16: None | J16: No | K16: Low | L16: No | M16: Closed | N16: None | O16: =_xlfn.XLOOKUP(A16, restaurant_cuisines!A:A,restaurant_cuisines!B:B,"Not Found") -> Mexican
A17: 132665 | B17: Tacos Correcaminos | C17: Ciudad Victoria | D17: Tamaulipas | E17: Mexico | G17: 23.736798 | H17: -99.134241 | I17: None | J17: No | K17: Low | L17: No | M17: Closed | N17: None | O17: =_xlfn.XLOOKUP(A17, restaurant_cuisines!A:A,restaurant_cuisines!B:B,"Not Found") -> Mexican
A18: 132667 | B18: Little Pizza Emilio Portes Gil | C18: Ciudad Victoria | D18: Tamaulipas | E18: Mexico | G18: 23.752697 | H18: -99.163359 | I18: None | J18: No | K18: Low | L18: Yes | M18: Closed | N18: None | O18: =_xlfn.XLOOKUP(A18, restaurant_cuisines!A:A,restaurant_cuisines!B:B,"Not Found") -> Armenian
... A23: 132723 | B23: Gordas De Morales | C23: San Luis Potosi | D23: San Luis Potosi | E23: Mexico | G23: 22.148934 | H23: -101.01985 | I23: Full Bar | J23: Smoking Section | K23: Medium | L23: No | M23: Closed | N23: Public | O23: =_xlfn.XLOOKUP(A23, restaurant_cuisines!A:A,restaurant_cuisines!B:B,"Not Found") -> Mexican
A24: 132732 | B24: Taqueria El Amigo | C24: Ciudad Victoria | D24: Tamaulipas | E24: Mexico | F24: 87018 | G24: 23.754357 | H24: -99.171288 | I24: None | J24: No | K24: Low | L24: No | M24: Open | N24: None | O24: =_xlfn.XLOOKUP(A24, restaurant_cuisines!A:A,restaurant_cuisines!B:B,"Not Found") -> Mexican
A25: 132733 | B25: Little Caesars | C25: Ciudad Victoria | D25: Tamaulipas | E25: Mexico | G25: 23.752707 | H25: -99.162565 | I25: None | J25: No | K25: Medium | L25: Yes | M25: Closed | N25: Yes | O25: =_xlfn.XLOOKUP(A25, restaurant_cuisines!A:A,restaurant_cuisines!B:B,"Not Found") -> Pizzeria
A26: 132740 | B26: Carreton De Flautas Y Migadas | C26: Ciudad Victoria | D26: Tamaulipas | E26: Mexico | G26: 23.752197 | H26: -99.166632 | I26: None | J26: Yes | K26: Low | L26: No | M26: Open | N26: None | O26: =_xlfn.XLOOKUP(A26, restaurant_cuisines!A:A,restaurant_cuisines!B:B,"Not Found") -> Mexican
A27: 132754 | B27: Cabana Huasteca | C27: San Luis Potosi | D27: San Luis Potosi | E27: Mexico | G27: 22.147738 | H27: -100.99062 | I27: None | J27: No | K27: Medium | L27: No | M27: Closed | N27: None | O27: =_xlfn.XLOOKUP(A27, restaurant_cuisines!A:A,restaurant_cuisines!B:B,"Not Found") -> Mexican
A28: 132755 | B28: La Estrella De Dimas | C28: San Luis Potosi | D28: San Luis Potosi | E28: Mexico | G28: 22.153324 | H28: -101.01955 | I28: None | J28: No | K28: Medium | L28: No | M28: Closed | N28: Public | O28: =_xlfn.XLOOKUP(A28, restaurant_cuisines!A:A,restaurant_cuisines!B:B,"Not Found") -> Mexican
A29: 132766 | B29: Mikasa | C29: Cuernavaca | D29: Morelos | E29: Mexico | G29: 18.910178 | H29: -99.231544 | I29: Wine & Beer | J29: No | K29: Medium | L29: No | M29: Closed | N29: Yes | O29: =_xlfn.XLOOKUP(A29, restaurant_cuisines!A:A,restaurant_cuisines!B:B,"Not Found") -> Japanese
A30: 132767 | B30: Restaurant Familiar El Chino | C30: Jiutepec | D30: Morelos | E30: Mexico | G30: 18.882087 | H30: -99.163027 | I30: Wine & Beer | J30: Yes | K30: Medium | L30: No | M30: Open | N30: Yes | O30: =_xlfn.XLOOKUP(A30, restaurant_cuisines!A:A,restaurant_cuisines!B:B,"Not Found") -> Vietnamese
A31: 132768 | B31: Mariscos Tia Licha | C31: Cuernavaca | D31: Morelos | E31: Mexico | F31: 62320 | G31: 18.925773 | H31: -99.232636 | I31: None | J31: No | K31: Medium | L31: Yes | M31: Closed | N31: None | O31: =_xlfn.XLOOKUP(A31, restaurant_cuisines!A:A,restaurant_cuisines!B:B,"Not Found") -> Family
A32: 132773 | B32: El Cotorreo | C32: Cuernavaca | D32: Morelos | E32: Mexico | G32: 18.869993 | H32: -99.210319 | I32: Wine & Beer | J32: Yes | K32: Low | L32: No | M32: Open | N32: None | O32: =_xlfn.XLOOKUP(A32, restaurant_cuisines!A:A,restaurant_cuisines!B:B,"Not Found") -> Family
A33: 132825 | B33: Puesto De Tacos | C33: San Luis Potosi | D33: San Luis Potosi | E33: Mexico | F33: 78280 | G33: 22.147392 | H33: -100.98309 | I33: None | J33: No | K33: Low | L33: No | M33: Open | N33: None | O33: =_xlfn.XLOOKUP(A33, restaurant_cuisines!A:A,restaurant_cuisines!B:B,"Not Found") -> Mexican
A34: 132830 | B34: Rincon Huasteco | C34: San Luis Potosi | D34: San Luis Potosi | E34: Mexico | G34: 22.150849 | H34: -100.93975 | I34: None | J34: No | K34: Low | L34: No | M34: Closed | N34: None | O34: =_xlfn.XLOOKUP(A34, restaurant_cuisines!A:A,restaurant_cuisines!B:B,"Not Found") -> Not Found
A35: 132834 | B35: Gorditas Doa Gloria | C35: San Luis Potosi | D35: San Luis Potosi | E35: Mexico | F35: 78349 | G35: 22.156469 | H35: -100.98554 | I35: None | J35: No | K35: Low | L35: No | M35: Closed | N35: Public | O35: =_xlfn.XLOOKUP(A35, restaurant_cuisines!A:A,restaurant_cuisines!B:B,"Not Found") -> Mexican
A36: 132845 | B36: Cenaduria El Rincón De Tlaquepaque | C36: San Luis Potosi | D36: San Luis Potosi | E36: Mexico | G36: 22.126293 | H36: -100.90078 | I36: None | J36: No | K36: Medium | L36: No | M36: Closed | N36: None | O36: =_xlfn.XLOOKUP(A36, restaurant_cuisines!A:A,restaurant_cuisines!B:B,"Not Found") -> Mexican
A37: 132846 | B37: El Lechon Potosino | C37: San Luis Potosi | D37: San Luis Potosi | E37: Mexico | G37: 22.142273 | H37: -100.94265 | I37: None | J37: Yes | K37: Low | L37: No | M37: Open | N37: None | O37: =_xlfn.XLOOKUP(A37, restaurant_cuisines!A:A,restaurant_cuisines!B:B,"Not Found") -> International
A38: 132847 | B38: Don Burguers | C38: San Luis Potosi | D38: San Luis Potosi | E38: Mexico | G38: 22.144337 | H38: -100.93738 | I38: None | J38: No | K38: Low | L38: No | M38: Open | N38: None | O38: =_xlfn.XLOOKUP(A38, restaurant_cuisines!A:A,restaurant_cuisines!B:B,"Not Found") -> Not Found
A39: 132851 | B39: KFC | C39: San Luis Potosi | D39: San Luis Potosi | E39: Mexico | G39: 22.136872 | H39: -100.93457 | I39: None | J39: No | K39: Low | L39: No | M39: Closed | N39: Yes | O39: =_xlfn.XLOOKUP(A39, restaurant_cuisines!A:A,restaurant_cuisines!B:B,"Not Found") -> American
A40: 132854 | B40: Sirlone | C40: San Luis Potosi | D40: San Luis Potosi | E40: Mexico | G40: 22.137863 | H40: -100.93833 | I40: Wine & Beer | J40: No | K40: Medium | L40: No | M40: Closed | N40: Yes | O40: =_xlfn.XLOOKUP(A40, restaurant_cuisines!A:A,restaurant_cuisines!B:B,"Not Found") -> International
A41: 132856 | B41: Unicol's Pizza | C41: San Luis Potosi | D41: San Luis Potosi | E41: Mexico | G41: 22.151378 | H41: -100.97463 | I41: Wine & Beer | J41: No | K41: Low | L41: No | M41: Closed | N41: None | O41: =_xlfn.XLOOKUP(A41, restaurant_cuisines!A:A,restaurant_cuisines!B:B,"Not Found") -> Italian
A42: 132858 | B42: Hamburguesas Valle Dorado | C42: San Luis Potosi | D42: San Luis Potosi | E42: Mexico | G42: 22.131292 | H42: -100.93719 | I42: None | J42: No | K42: Low | L42: No | M42: Closed | N42: None | O42: =_xlfn.XLOOKUP(A42, restaurant_cuisines!A:A,restaurant_cuisines!B:B,"Not Found") -> Burgers
A43: 132861 | B43: Carl's Jr | C43: San Luis Potosi | D43: San Luis Potosi | E43: Mexico | G43: 22.148097 | H43: -101.0173 | I43: None | J43: No | K43: Medium | L43: Yes | M43: Closed | N43: Yes | O43: =_xlfn.XLOOKUP(A43, restaurant_cuisines!A:A,restaurant_cuisines!B:B,"Not Found") -> Burgers
A44: 132862 | B44: La Posada Del Virrey | C44: San Luis Potosi | D44: San Luis Potosi | E44: Mexico | G44: 22.150643 | H44: -100.98701 | I44: Wine & Beer | J44: No | K44: High | L44: No | M44: Closed | N44: Valet | O44: =_xlfn.XLOOKUP(A44, restaurant_cuisines!A:A,restaurant_cuisines!B:B,"Not Found") -> International
...

Sheet RestaurantCuisineTable
A1: Restaurant_ID | B1: Cuisine
A2: 132560 | B2: Regional
A3: 132572 | B3: Cafeteria
A4: 132583 | B4: American
A5: 132584 | B5: Mexican
A6: 132594 | B6: Mexican
A7: 132608 | B7: Mexican
A8: 132609 | B8: Fast Food
A9: 132613 | B9: Mexican
A10: 132626 | B10: Italian
A11: 132630 | B11: Mexican
A12: 132663 | B12: Mexican
A13: 132665 | B13: Mexican
... A113: 135109 | B113: Italian

Sheet restaurant_cuisines
A1: Restaurant_ID | B1: Cuisine
A2: 132560 | B2: Regional
A3: 132572 | B3: Cafeteria
A4: 132583 | B4: American
A5: 132584 | B5: Mexican
A6: 132594 | B6: Mexican
A7: 132608 | B7: Mexican
A8: 132609 | B8: Fast Food
A9: 132613 | B9: Mexican
A10: 132626 | B10: Italian
A11: 132630 | B11: Mexican
A12: 132663 | B12: Mexican
A13: 132665 | B13: Mexican
... A113: 135109 | B113: Italian

Sheet MasterSheet (2)
A1: Consumer_ID | B1: Restaurant_ID | C1: Consumer_Preferred_Cuisine | D1: Consumer_City | E1: Consumer_State | F1: Consumer_Country | G1: Consumer_Latitude | H1: Consumer_Longitude | I1: Consumer_Smoker | J1: Consumer_Drink_Level | K1: Consumer_Transportation_Method | L1: Consumer_Marital_Status | M1: Consumer_Children | N1: Consumer_Age | O1: Consumer_Age_Group | P1: Consumer_Occupation | Q1: Consumer_Budget | R1: Overall_Rating | S1: Food_Rating | T1: Service_Rating | U1: Restaurant_Name | V1: Restaurant_Cuisine | W1: Restaurant_City | X1: Restaurant_State | Y1: Restaurant_Country | Z1: Restaurant_Zip_Code | AA1: Restaurant_Latitude | AB1: Restaurant_Longitude | AC1: Restaurant_Alcohol_Service | AD1: Restaurant_Smoking_Allowed | AE1: Restaurant_Price | AF1: Restaurant_Franchise | AG1: Restaurant_Area | AH1: Restaurant_Parking
A2: U1067 | B2: 132560 | C2: Mexican | D2: Ciudad Victoria | E2: Tamaulipas | F2: Mexico | G2: 23.752269 | H2: -99.168605 | I2: No | J2: Abstemious | K2: Public | L2: Single | M2: Independent | N2: 25 | O2: Young Adult | P2: Student | Q2: Medium | R2: 1 | S2: 0 | T2: 0 | U2: Puesto De Gorditas | V2: Regional | W2: Ciudad Victoria | X2: Tamaulipas | Y2: Mexico | AA2: 23.752304 | AB2: -99.166913 | AC2: None | AD2: Yes | AE2: Low | AF2: No | AG2: Open | AH2: Public
A3: U1082 | B3: 132560 | C3: Mexican | D3: Ciudad Victoria | E3: Tamaulipas | F3: Mexico | G3: 23.753061 | H3: -99.166095 | I3: Yes | J3: Abstemious | K3: Public | L3: Single | M3: Unknown | N3: 23 | O3: Young Adult | P3: Student | Q3: Medium | R3: 0 | S3: 0 | T3: 0 | U3: Puesto De Gorditas | V3: Regional | W3: Ciudad Victoria | X3: Tamaulipas | Y3: Mexico | AA3: 23.752304 | AB3: -99.166913 | AC3: None | AD3: Yes | AE3: Low | AF3: No | AG3: Open | AH3: Public
A4: U1050 | B4: 132560 | C4: Mexican | D4: Ciudad Victoria | E4: Tamaulipas | F4: Mexico | G4: 23.758815 | H4: -99.171216 | I4: No | J4: Social Drinker | K4: Car | L4: Single | M4: Independent | N4: 23 | O4: Young Adult | P4: Student | Q4: Medium | R4: 0 | S4: 2 | T4: 0 | U4: Puesto De Gorditas | V4: Regional | W4: Ciudad Victoria | X4: Tamaulipas | Y4: Mexico | AA4: 23.752304 | AB4: -99.166913 | AC4: None | AD4: Yes | AE4: Low | AF4: No | AG4: Open | AH4: Public
A5: U1087 | B5: 132560 | C5: Chinese | D5: Ciudad Victoria | E5: Tamaulipas | F5: Mexico | G5: 23.753336 | H5: -99.167984 | I5: No | J5: Abstemious | K5: Public | L5: Single | M5: Independent | N5: 23 | O5: Young Adult | P5: Student | Q5: Medium | R5: 1 | S5: 2 | T5: 1 | U5: Puesto De Gorditas | V5: Regional | W5: Ciudad Victoria | X5: Tamaulipas | Y5: Mexico | AA5: 23.752304 | AB5: -99.166913 | AC5: None | AD5: Yes | AE5: Low | AF5: No | AG5: Open | AH5: Public
A6: U1083 | B6: 132572 | C6: Mexican | D6: San Luis Potosi | E6: San Luis Potosi | F6: Mexico | G6: 22.13392 | H6: -101.02837 | I6: No | J6: Abstemious | K6: Unknown | L6: Unknown | M6: Unknown | N6: 31 | O6: Young Adult | P6: Unknown | Q6: Unknown | R6: 2 | S6: 2 | T6: 2 | U6: Cafe Chaires | V6: Cafeteria | W6: San Luis Potosi | X6: San Luis Potosi | Y6: Mexico | AA6: 22.141647 | AB6: -100.99271 | AC6: None | AD6: No | AE6: Low | AF6: No | AG6: Closed | AH6: Yes
A7: U1108 | B7: 132572 | C7: Coffee Shop | D7: San Luis Potosi | E7: San Luis Potosi | F7: Mexico | G7: 22.143524 | H7: -100.98756 | I7: No | J7: Abstemious | K7: Public | L7: Single | M7: Independent | N7: 29 | O7: Young Adult | P7: Student | Q7: Medium | R7: 1 | S7: 2 | T7: 1 | U7: Cafe Chaires | V7: Cafeteria | W7: San Luis Potosi | X7: San Luis Potosi | Y7: Mexico | AA7: 22.141647 | AB7: -100.99271 | AC7: None | AD7: No | AE7: Low | AF7: No | AG7: Closed | AH7: Yes
A8: U1108 | B8: 132572 | C8: Sushi | D8: San Luis Potosi | E8: San Luis Potosi | F8: Mexico | G8: 22.143524 | H8: -100.98756 | I8: No | J8: Abstemious | K8: Public | L8: Single | M8: Independent | N8: 29 | O8: Young Adult | P8: Student | Q8: Medium | R8: 1 | S8: 2 | T8: 1 | U8: Cafe Chaires | V8: Cafeteria | W8: San Luis Potosi | X8: San Luis Potosi | Y8: Mexico | AA8: 22.141647 | AB8: -100.99271 | AC8: None | AD8: No | AE8: Low | AF8: No | AG8: Closed | AH8: Yes
A9: U1108 | B9: 132572 | C9: Latin American | D9: San Luis Potosi | E9: San Luis Potosi | F9: Mexico | G9: 22.143524 | H9: -100.98756 | I9: No | J9: Abstemious | K9: Public | L9: Single | M9: Independent | N9: 29 | O9: Young Adult | P9: Student | Q9: Medium | R9: 1 | S9: 2 | T9: 1 | U9: Cafe Chaires | V9: Cafeteria | W9: San Luis Potosi | X9: San Luis Potosi | Y9: Mexico | AA9: 22.141647 | AB9: -100.99271 | AC9: None | AD9: No | AE9: Low | AF9: No | AG9: Closed | AH9: Yes
A10: U1108 | B10: 132572 | C10: Deli | D10: San Luis Potosi | E10: San Luis Potosi | F10: Mexico | G10: 22.143524 | H10: -100.98756 | I10: No | J10: Abstemious | K10: Public | L10: Single | M10: Independent | N10: 29 | O10: Young Adult | P10: Student | Q10: Medium | R10: 1 | S10: 2 | T10: 1 | U10: Cafe Chaires | V10: Cafeteria | W10: San Luis Potosi | X10: San Luis Potosi | Y10: Mexico | AA10: 22.141647 | AB10: -100.99271 | AC10: None | AD10: No | AE10: Low | AF10: No | AG10: Closed | AH10: Yes
A11: U1108 | B11: 132572 | C11: Mexican | D11: San Luis Potosi | E11: San Luis Potosi | F11: Mexico | G11: 22.143524 | H11: -100.98756 | I11: No | J11: Abstemious | K11: Public | L11: Single | M11: Independent | N11: 29 | O11: Young Adult | P11: Student | Q11: Medium | R11: 1 | S11: 2 | T11: 1 | U11: Cafe Chaires | V11: Cafeteria | W11: San Luis Potosi | X11: San Luis Potosi | Y11: Mexico | AA11: 22.141647 | AB11: -100.99271 | AC11: None | AD11: No | AE11: Low | AF11: No | AG11: Closed | AH11: Yes
A12: U1108 | B12: 132572 | C12: Hot Dogs | D12: San Luis Potosi | E12: San Luis Potosi | F12: Mexico | G12: 22.143524 | H12: -100.98756 | I12: No | J12: Abstemious | K12: Public | L12: Single | M12: Independent | N12: 29 | O12: Young Adult | P12: Student | Q12: Medium | R12: 1 | S12: 2 | T12: 1 | U12: Cafe Chaires | V12: Cafeteria | W12: San Luis Potosi | X12: San Luis Potosi | Y12: Mexico | AA12: 22.141647 | AB12: -100.99271 | AC12: None | AD12: No | AE12: Low | AF12: No | AG12: Closed | AH12: Yes
A13: U1108 | B13: 132572 | C13: American | D13: San Luis Potosi | E13: San Luis Potosi | F13: Mexico | G13: 22.143524 | H13: -100.98756 | I13: No | J13: Abstemious | K13: Public | L13: Single | M13: Independent | N13: 29 | O13: Young Adult | P13: Student | Q13: Medium | R13: 1 | S13: 2 | T13: 1 | U13: Cafe Chaires | V13: Cafeteria | W13: San Luis Potosi | X13: San Luis Potosi | Y13: Mexico | AA13: 22.141647 | AB13: -100.99271 | AC13: None | AD13: No | AE13: Low | AF13: No | AG13: Closed | AH13: Yes
... A38: U1073 | B38: 132572 | C38: American | D38: San Luis Potosi | E38: San Luis Potosi | F38: Mexico | G38: 22.15 | H38: -100.983 | I38: No | J38: Abstemious | K38: Car | L38: Single | M38: Kids | N38: 23 | O38: Young Adult | P38: Unemployed | Q38: Medium | R38: 0 | S38: 0 | T38: 0 | U38: Cafe Chaires | V38: Cafeteria | W38: San Luis Potosi | X38: San Luis Potosi | Y38: Mexico | AA38: 22.141647 | AB38: -100.99271 | AC38: None | AD38: No | AE38: Low | AF38: No | AG38: Closed | AH38: Yes
A39: U1044 | B39: 132583 | C39: Mexican | D39: Cuernavaca | E39: Morelos | F39: Mexico | G39: 18.95298 | H39: -99.260789 | I39: Yes | J39: Social Drinker | K39: Car | L39: Married | M39: Kids | N39: 43 | O39: Young Adult | P39: Employed | Q39: Medium | R39: 1 | S39: 2 | T39: 1 | U39: Mcdonalds Centro | V39: American | W39: Cuernavaca | X39: Morelos | Y39: Mexico | Z39: 62000 | AA39: 18.92229 | AB39: -99.234332 | AC39: None | AD39: No | AE39: Low | AF39: Yes | AG39: Closed | AH39: None
A40: U1035 | B40: 132583 | C40: Family | D40: Cuernavaca | E40: Morelos | F40: Mexico | G40: 18.839671 | H40: -99.223897 | I40: Yes | J40: Casual Drinker | K40: Car | L40: Single | M40: Independent | N40: 27 | O40: Young Adult | P40: Student | Q40: Medium | R40: 1 | S40: 0 | T40: 2 | U40: Mcdonalds Centro | V40: American | W40: Cuernavaca | X40: Morelos | Y40: Mexico | Z40: 62000 | AA40: 18.92229 | AB40: -99.234332 | AC40: None | AD40: No | AE40: Low | AF40: Yes | AG40: Closed | AH40: None
A41: U1118 | B41: 132583 | C41: Pizzeria | D41: Cuernavaca | E41: Morelos | F41: Mexico | G41: 18.940062 | H41: -99.228172 | I41: Yes | J41: Casual Drinker | K41: Public | L41: Single | M41: Independent | N41: 25 | O41: Young Adult | P41: Student | Q41: Medium | R41: 0 | S41: 0 | T41: 0 | U41: Mcdonalds Centro | V41: American | W41: Cuernavaca | X41: Morelos | Y41: Mexico | Z41: 62000 | AA41: 18.92229 | AB41: -99.234332 | AC41: None | AD41: No | AE41: Low | AF41: Yes | AG41: Closed | AH41: None
A42: U1119 | B42: 132583 | C42: Mexican | D42: Cuernavaca | E42: Morelos | F42: Mexico | G42: 18.96479 | H42: -99.260017 | I42: No | J42: Abstemious | K42: Public | L42: Single | M42: Independent | N42: 20 | O42: Young Adult | P42: Student | Q42: Medium | R42: 2 | S42: 2 | T42: 2 | U42: Mcdonalds Centro | V42: American | W42: Cuernavaca | X42: Morelos | Y42: Mexico | Z42: 62000 | AA42: 18.92229 | AB42: -99.234332 | AC42: None | AD42: No | AE42: Low | AF42: Yes | AG42: Closed | AH42: None
